[2024-10-23T01:09:01.559+0000] {taskinstance.py:1125} INFO - Dependencies all met for dep_context=non-requeueable deps ti=<TaskInstance: telegram_bot_dag.run_bot_notebook scheduled__2024-10-23T01:08:00+00:00 [queued]>
[2024-10-23T01:09:01.563+0000] {taskinstance.py:1125} INFO - Dependencies all met for dep_context=requeueable deps ti=<TaskInstance: telegram_bot_dag.run_bot_notebook scheduled__2024-10-23T01:08:00+00:00 [queued]>
[2024-10-23T01:09:01.564+0000] {taskinstance.py:1331} INFO - Starting attempt 1 of 2
[2024-10-23T01:09:01.571+0000] {taskinstance.py:1350} INFO - Executing <Task(PythonOperator): run_bot_notebook> on 2024-10-23 01:08:00+00:00
[2024-10-23T01:09:01.574+0000] {standard_task_runner.py:57} INFO - Started process 276 to run task
[2024-10-23T01:09:01.576+0000] {standard_task_runner.py:84} INFO - Running: ['***', 'tasks', 'run', 'telegram_bot_dag', 'run_bot_notebook', 'scheduled__2024-10-23T01:08:00+00:00', '--job-id', '237', '--raw', '--subdir', 'DAGS_FOLDER/bot_dag.py', '--cfg-path', '/tmp/tmphvzn96qt']
[2024-10-23T01:09:01.579+0000] {standard_task_runner.py:85} INFO - Job 237: Subtask run_bot_notebook
[2024-10-23T01:09:01.622+0000] {task_command.py:410} INFO - Running <TaskInstance: telegram_bot_dag.run_bot_notebook scheduled__2024-10-23T01:08:00+00:00 [running]> on host 310c8e33116f
[2024-10-23T01:09:01.681+0000] {taskinstance.py:1570} INFO - Exporting env vars: AIRFLOW_CTX_DAG_OWNER='***' AIRFLOW_CTX_DAG_ID='telegram_bot_dag' AIRFLOW_CTX_TASK_ID='run_bot_notebook' AIRFLOW_CTX_EXECUTION_DATE='2024-10-23T01:08:00+00:00' AIRFLOW_CTX_TRY_NUMBER='1' AIRFLOW_CTX_DAG_RUN_ID='scheduled__2024-10-23T01:08:00+00:00'
[2024-10-23T01:09:01.738+0000] {taskinstance.py:1847} ERROR - Task failed with exception
Traceback (most recent call last):
  File "/opt/airflow/dags/bot_dag.py", line 15, in run_bot_notebook
    text=True
  File "/usr/local/lib/python3.7/subprocess.py", line 512, in run
    output=stdout, stderr=stderr)
subprocess.CalledProcessError: Command '['python', '/Users/klovak_stefan/post_bot/src/pbot.py']' returned non-zero exit status 2.

During handling of the above exception, another exception occurred:

Traceback (most recent call last):
  File "/home/airflow/.local/lib/python3.7/site-packages/airflow/operators/python.py", line 181, in execute
    return_value = self.execute_callable()
  File "/home/airflow/.local/lib/python3.7/site-packages/airflow/operators/python.py", line 198, in execute_callable
    return self.python_callable(*self.op_args, **self.op_kwargs)
  File "/opt/airflow/dags/bot_dag.py", line 19, in run_bot_notebook
    logging.error(f"Ошибка при запуске скрипта: {e.stderr}")
NameError: name 'logging' is not defined
[2024-10-23T01:09:01.746+0000] {taskinstance.py:1373} INFO - Marking task as UP_FOR_RETRY. dag_id=telegram_bot_dag, task_id=run_bot_notebook, execution_date=20241023T010800, start_date=20241023T010901, end_date=20241023T010901
[2024-10-23T01:09:01.754+0000] {standard_task_runner.py:109} ERROR - Failed to execute job 237 for task run_bot_notebook (name 'logging' is not defined; 276)
[2024-10-23T01:09:01.759+0000] {local_task_job_runner.py:232} INFO - Task exited with return code 1
[2024-10-23T01:09:01.772+0000] {taskinstance.py:2674} INFO - 0 downstream tasks scheduled from follow-on schedule check
